Workbook

Sheet Pacientes
A1: Nome | B1: Telefone | C1: Email | D1: Origem do Lead | E1: Procedimento de Interesse | F1: Responsável | G1: Data 1º Contato | H1: Marcou Consulta? | I1: Data da Consulta | J1: Compareceu? | K1: Fez Radiografia? | L1: Plano de Tratamento? | M1: Valor do Orçamento (R$) | N1: Fechou Tratamento? | O1: Valor Fechado (R$) | P1: Data Fechamento | Q1: Motivo da Perda | R1: Status Atual | S1: Observações | T1: OrdemStatus (aux) | U1: ChaveBusca (aux) | V1: MêsContato (aux) | W1: MêsFechamento (aux) | X1: ChaveFechado (aux) | Y1: OrdemIndicacao (aux) | Z1: ChaveIndicacao (aux) | AA1: MêsConsulta (aux)
A2: Andrea Reis Ferreira de Melo | B2: (31) 99804-0037 | D2: Indicação | E2: Invisaling | F2: Mariana | G2: 46205 | H2: Sim | I2: 46209 | J2: Sim | K2: Não | L2: Sim | M2: 15000 | N2: Não | Q2: Sem orçamento no momento | R2: =IF(N2="Sim","Fechado (Total)",IF(N2="Parcial","Fechado (Parcial)",IF(N2="Não","Perdido",IF(N2="Pendente","Pendente",IF(N2="Não precisa no momento","Não Precisa no Momento",IF(L2="Sim","Plano de Tratamento",IF(J2="Não","Não Compareceu",IF(J2="Sim","Compareceu",IF(H2="Não","Perdido",IF(H2="Sim","Consulta Marcada",IF(A2="","","Novo Paciente"))))))))))) -> Perdido | S2: Tem outras prioridades, não vai fazer | T2: =IF(A2="","",SUMPRODUCT(($R$2:R2=R2)*($A$2:A2<>""))) -> 1 | U2: =IF(A2="","",R2&"|"&T2) -> Perdido|1 | V2: =IF(G2="","",TEXT(G2,"mm/yyyy")) -> 07/2026 | W2: =IF(P2="","",TEXT(P2,"mm/yyyy")) | X2: =IF(A2="","",IF(OR(R2="Fechado (Total)",R2="Fechado (Parcial)"),"Fechado|"&SUMPRODUCT((($R$2:R2="Fechado (Total)")+($R$2:R2="Fechado (Parcial)"))*($A$2:A2<>"")),"")) | Y2: =IF(A2="","",IF(D2="Indicação",SUMPRODUCT(($D$2:D2="Indicação")*($A$2:A2<>"")),"")) -> 1 | Z2: =IF(Y2="","","Indicacao|"&Y2) -> Indicacao|1 | AA2: =IF(I2="","",TEXT(I2,"mm/yyyy")) -> 07/2026
A3: Julia da Silva Costa | B3: (31) 98479-0759 | D3: Instagram | E3: Invisaling | F3: Natalia | G3: 46202 | H3: Sim | I3: 46210 | J3: Sim | K3: Sim | L3: Sim | M3: 15000 | N3: Sim | O3: 14700 | P3: 46223 | R3: =IF(N3="Sim","Fechado (Total)",IF(N3="Parcial","Fechado (Parcial)",IF(N3="Não","Perdido",IF(N3="Pendente","Pendente",IF(N3="Não precisa no momento","Não Precisa no Momento",IF(L3="Sim","Plano de Tratamento",IF(J3="Não","Não Compareceu",IF(J3="Sim","Compareceu",IF(H3="Não","Perdido",IF(H3="Sim","Consulta Marcada",IF(A3="","","Novo Paciente"))))))))))) -> Fechado (Total) | T3: =IF(A3="","",SUMPRODUCT(($R$2:R3=R3)*($A$2:A3<>""))) -> 1 | U3: =IF(A3="","",R3&"|"&T3) -> Fechado (Total)|1 | V3: =IF(G3="","",TEXT(G3,"mm/yyyy")) -> 06/2026 | W3: =IF(P3="","",TEXT(P3,"mm/yyyy")) -> 07/2026 | X3: =IF(A3="","",IF(OR(R3="Fechado (Total)",R3="Fechado (Parcial)"),"Fechado|"&SUMPRODUCT((($R$2:R3="Fechado (Total)")+($R$2:R3="Fechado (Parcial)"))*($A$2:A3<>"")),"")) -> Fechado|1 | Y3: =IF(A3="","",IF(D3="Indicação",SUMPRODUCT(($D$2:D3="Indicação")*($A$2:A3<>"")),"")) | Z3: =IF(Y3="","","Indicacao|"&Y3) | AA3: =IF(I3="","",TEXT(I3,"mm/yyyy")) -> 07/2026
A4: Hiltonn Muniz Cordeiro | B4: (38) 9969-5811 | D4: Indicação | E4: Invisalign | F4: Mariana | G4: 46149 | H4: Sim | I4: 46169 | J4: Sim | K4: Sim | L4: Sim | M4: 16000 | N4: Não | Q4: Sem orçamento no momento | R4: =IF(N4="Sim","Fechado (Total)",IF(N4="Parcial","Fechado (Parcial)",IF(N4="Não","Perdido",IF(N4="Pendente","Pendente",IF(N4="Não precisa no momento","Não Precisa no Momento",IF(L4="Sim","Plano de Tratamento",IF(J4="Não","Não Compareceu",IF(J4="Sim","Compareceu",IF(H4="Não","Perdido",IF(H4="Sim","Consulta Marcada",IF(A4="","","Novo Paciente"))))))))))) -> Perdido | S4: gastou muito com Dr Marcelo | T4: =IF(A4="","",SUMPRODUCT(($R$2:R4=R4)*($A$2:A4<>""))) -> 2 | U4: =IF(A4="","",R4&"|"&T4) -> Perdido|2 | V4: =IF(G4="","",TEXT(G4,"mm/yyyy")) -> 05/2026 | W4: =IF(P4="","",TEXT(P4,"mm/yyyy")) | X4: =IF(A4="","",IF(OR(R4="Fechado (Total)",R4="Fechado (Parcial)"),"Fechado|"&SUMPRODUCT((($R$2:R4="Fechado (Total)")+($R$2:R4="Fechado (Parcial)"))*($A$2:A4<>"")),"")) | Y4: =IF(A4="","",IF(D4="Indicação",SUMPRODUCT(($D$2:D4="Indicação")*($A$2:A4<>"")),"")) -> 2 | Z4: =IF(Y4="","","Indicacao|"&Y4) -> Indicacao|2 | AA4: =IF(I4="","",TEXT(I4,"mm/yyyy")) -> 05/2026
A5: Fernanda Bueno Teixeira Costa | B5: (31) 7332-8212 | C5: nandabtc@gmail.com | D5: já é paciente | E5: Invisalign | F5: Natalia | G5: 46184 | H5: Sim | I5: 46190 | J5: Sim | K5: Sim | L5: Sim | M5: 12000 | N5: Sim | O5: 11400 | P5: 46211 | R5: =IF(N5="Sim","Fechado (Total)",IF(N5="Parcial","Fechado (Parcial)",IF(N5="Não","Perdido",IF(N5="Pendente","Pendente",IF(N5="Não precisa no momento","Não Precisa no Momento",IF(L5="Sim","Plano de Tratamento",IF(J5="Não","Não Compareceu",IF(J5="Sim","Compareceu",IF(H5="Não","Perdido",IF(H5="Sim","Consulta Marcada",IF(A5="","","Novo Paciente"))))))))))) -> Fechado (Total) | T5: =IF(A5="","",SUMPRODUCT(($R$2:R5=R5)*($A$2:A5<>""))) -> 2 | U5: =IF(A5="","",R5&"|"&T5) -> Fechado (Total)|2 | V5: =IF(G5="","",TEXT(G5,"mm/yyyy")) -> 06/2026 | W5: =IF(P5="","",TEXT(P5,"mm/yyyy")) -> 07/2026 | X5: =IF(A5="","",IF(OR(R5="Fechado (Total)",R5="Fechado (Parcial)"),"Fechado|"&SUMPRODUCT((($R$2:R5="Fechado (Total)")+($R$2:R5="Fechado (Parcial)"))*($A$2:A5<>"")),"")) -> Fechado|2 | Y5: =IF(A5="","",IF(D5="Indicação",SUMPRODUCT(($D$2:D5="Indicação")*($A$2:A5<>"")),"")) | Z5: =IF(Y5="","","Indicacao|"&Y5) | AA5: =IF(I5="","",TEXT(I5,"mm/yyyy")) -> 06/2026
A6: Estevão Nobre Carrato | B6: (31) 8823-0811 | C6: estevaonc@gmail.com | D6: Indicação | E6: Invisalign | F6: Mariana | G6: 46233 | H6: Sim | I6: 46204 | J6: Sim | K6: Sim | L6: Sim | M6: 15000 | N6: Não | Q6: Sem orçamento no momento | R6: =IF(N6="Sim","Fechado (Total)",IF(N6="Parcial","Fechado (Parcial)",IF(N6="Não","Perdido",IF(N6="Pendente","Pendente",IF(N6="Não precisa no momento","Não Precisa no Momento",IF(L6="Sim","Plano de Tratamento",IF(J6="Não","Não Compareceu",IF(J6="Sim","Compareceu",IF(H6="Não","Perdido",IF(H6="Sim","Consulta Marcada",IF(A6="","","Novo Paciente"))))))))))) -> Perdido | S6: Quebrou um dente e vai fazer implante primeiro | T6: =IF(A6="","",SUMPRODUCT(($R$2:R6=R6)*($A$2:A6<>""))) -> 3 | U6: =IF(A6="","",R6&"|"&T6) -> Perdido|3 | V6: =IF(G6="","",TEXT(G6,"mm/yyyy")) -> 07/2026 | W6: =IF(P6="","",TEXT(P6,"mm/yyyy")) | X6: =IF(A6="","",IF(OR(R6="Fechado (Total)",R6="Fechado (Parcial)"),"Fechado|"&SUMPRODUCT((($R$2:R6="Fechado (Total)")+($R$2:R6="Fechado (Parcial)"))*($A$2:A6<>"")),"")) | Y6: =IF(A6="","",IF(D6="Indicação",SUMPRODUCT(($D$2:D6="Indicação")*($A$2:A6<>"")),"")) -> 3 | Z6: =IF(Y6="","","Indicacao|"&Y6) -> Indicacao|3 | AA6: =IF(I6="","",TEXT(I6,"mm/yyyy")) -> 07/2026
A7: Guilherme Moraes | B7: 236 979 1253 | C7: guilerme.moraes@outlook.com | D7: Indicação | E7: Invisalign | F7: Mariana | G7: 46217 | H7: Sim | I7: 46218 | J7: Sim | K7: Sim | L7: Sim | M7: 8924 | N7: Sim | O7: 8567.86 | P7: 46226 | R7: =IF(N7="Sim","Fechado (Total)",IF(N7="Parcial","Fechado (Parcial)",IF(N7="Não","Perdido",IF(N7="Pendente","Pendente",IF(N7="Não precisa no momento","Não Precisa no Momento",IF(L7="Sim","Plano de Tratamento",IF(J7="Não","Não Compareceu",IF(J7="Sim","Compareceu",IF(H7="Não","Perdido",IF(H7="Sim","Consulta Marcada",IF(A7="","","Novo Paciente"))))))))))) -> Fechado (Total) | T7: =IF(A7="","",SUMPRODUCT(($R$2:R7=R7)*($A$2:A7<>""))) -> 3 | U7: =IF(A7="","",R7&"|"&T7) -> Fechado (Total)|3 | V7: =IF(G7="","",TEXT(G7,"mm/yyyy")) -> 07/2026 | W7: =IF(P7="","",TEXT(P7,"mm/yyyy")) -> 07/2026 | X7: =IF(A7="","",IF(OR(R7="Fechado (Total)",R7="Fechado (Parcial)"),"Fechado|"&SUMPRODUCT((($R$2:R7="Fechado (Total)")+($R$2:R7="Fechado (Parcial)"))*($A$2:A7<>"")),"")) -> Fechado|3 | Y7: =IF(A7="","",IF(D7="Indicação",SUMPRODUCT(($D$2:D7="Indicação")*($A$2:A7<>"")),"")) -> 4 | Z7: =IF(Y7="","","Indicacao|"&Y7) -> Indicacao|4 | AA7: =IF(I7="","",TEXT(I7,"mm/yyyy")) -> 07/2026
A8: Bernardo Vieira Bersan El Bizri | B8: (31) 8499-8630 | D8: Indicação | E8: Aparelho Disjuntor | F8: Mariana | G8: 46153 | H8: Sim | I8: 46204 | J8: Sim | K8: Sim | L8: Sim | M8: 4000 | N8: Sim | O8: 3433.17 | P8: 46220 | R8: =IF(N8="Sim","Fechado (Total)",IF(N8="Parcial","Fechado (Parcial)",IF(N8="Não","Perdido",IF(N8="Pendente","Pendente",IF(N8="Não precisa no momento","Não Precisa no Momento",IF(L8="Sim","Plano de Tratamento",IF(J8="Não","Não Compareceu",IF(J8="Sim","Compareceu",IF(H8="Não","Perdido",IF(H8="Sim","Consulta Marcada",IF(A8="","","Novo Paciente"))))))))))) -> Fechado (Total) | T8: =IF(A8="","",SUMPRODUCT(($R$2:R8=R8)*($A$2:A8<>""))) -> 4 | U8: =IF(A8="","",R8&"|"&T8) -> Fechado (Total)|4 | V8: =IF(G8="","",TEXT(G8,"mm/yyyy")) -> 05/2026 | W8: =IF(P8="","",TEXT(P8,"mm/yyyy")) -> 07/2026 | X8: =IF(A8="","",IF(OR(R8="Fechado (Total)",R8="Fechado (Parcial)"),"Fechado|"&SUMPRODUCT((($R$2:R8="Fechado (Total)")+($R$2:R8="Fechado (Parcial)"))*($A$2:A8<>"")),"")) -> Fechado|4 | Y8: =IF(A8="","",IF(D8="Indicação",SUMPRODUCT(($D$2:D8="Indicação")*($A$2:A8<>"")),"")) -> 5 | Z8: =IF(Y8="","","Indicacao|"&Y8) -> Indicacao|5 | AA8: =IF(I8="","",TEXT(I8,"mm/yyyy")) -> 07/2026
A9: Esther Andrade dos Santos | B9: (31) 99387-5247 | C9: cristinamca1@hotmail.com | D9: Indicação | E9: Aparelho Fixo Metálico | F9: Mariana | G9: 45845 | H9: Sim | I9: 46205 | J9: Sim | K9: Sim | L9: Sim | M9: 4000 | N9: Pendente | Q9: Retorna mais para frente | R9: =IF(N9="Sim","Fechado (Total)",IF(N9="Parcial","Fechado (Parcial)",IF(N9="Não","Perdido",IF(N9="Pendente","Pendente",IF(N9="Não precisa no momento","Não Precisa no Momento",IF(L9="Sim","Plano de Tratamento",IF(J9="Não","Não Compareceu",IF(J9="Sim","Compareceu",IF(H9="Não","Perdido",IF(H9="Sim","Consulta Marcada",IF(A9="","","Novo Paciente"))))))))))) -> Pendente | S9: Quer preparar a filha para o aparelho fixo (hyrax e grade) / Chamar em Dezembro | T9: =IF(A9="","",SUMPRODUCT(($R$2:R9=R9)*($A$2:A9<>""))) -> 1 | U9: =IF(A9="","",R9&"|"&T9) -> Pendente|1 | V9: =IF(G9="","",TEXT(G9,"mm/yyyy")) -> 07/2025 | W9: =IF(P9="","",TEXT(P9,"mm/yyyy")) | X9: =IF(A9="","",IF(OR(R9="Fechado (Total)",R9="Fechado (Parcial)"),"Fechado|"&SUMPRODUCT((($R$2:R9="Fechado (Total)")+($R$2:R9="Fechado (Parcial)"))*($A$2:A9<>"")),"")) | Y9: =IF(A9="","",IF(D9="Indicação",SUMPRODUCT(($D$2:D9="Indicação")*($A$2:A9<>"")),"")) -> 6 | Z9: =IF(Y9="","","Indicacao|"&Y9) -> Indicacao|6 | AA9: =IF(I9="","",TEXT(I9,"mm/yyyy")) -> 07/2026
A10: Miguel Gonzalez Bidoia | B10: (31) 98332-3412 | C10: paulobidoia@gmail.com | D10: Indicação | E10: Aparelho Disjuntor | F10: Natalia | G10: 46205 | H10: Sim | I10: 46205 | J10: Sim | K10: Sim | L10: Sim | M10: 7000 | N10: Sim | O10: 6650 | P10: 46218 | R10: =IF(N10="Sim","Fechado (Total)",IF(N10="Parcial","Fechado (Parcial)",IF(N10="Não","Perdido",IF(N10="Pendente","Pendente",IF(N10="Não precisa no momento","Não Precisa no Momento",IF(L10="Sim","Plano de Tratamento",IF(J10="Não","Não Compareceu",IF(J10="Sim","Compareceu",IF(H10="Não","Perdido",IF(H10="Sim","Consulta Marcada",IF(A10="","","Novo Paciente"))))))))))) -> Fechado (Total) | T10: =IF(A10="","",SUMPRODUCT(($R$2:R10=R10)*($A$2:A10<>""))) -> 5 | U10: =IF(A10="","",R10&"|"&T10) -> Fechado (Total)|5 | V10: =IF(G10="","",TEXT(G10,"mm/yyyy")) -> 07/2026 | W10: =IF(P10="","",TEXT(P10,"mm/yyyy")) -> 07/2026 | X10: =IF(A10="","",IF(OR(R10="Fechado (Total)",R10="Fechado (Parcial)"),"Fechado|"&SUMPRODUCT((($R$2:R10="Fechado (Total)")+($R$2:R10="Fechado (Parcial)"))*($A$2:A10<>"")),"")) -> Fechado|5 | Y10: =IF(A10="","",IF(D10="Indicação",SUMPRODUCT(($D$2:D10="Indicação")*($A$2:A10<>"")),"")) -> 7 | Z10: =IF(Y10="","","Indicacao|"&Y10) -> Indicacao|7 | AA10: =IF(I10="","",TEXT(I10,"mm/yyyy")) -> 07/2026
A11: Felipe Ribeiro Tostes de Menezes | B11: (12) 98123-9143 | D11: Indicação | E11: Aparelho Disjuntor | F11: Mariana | G11: 46210 | H11: Sim | I11: 46212 | J11: Sim | K11: Sim | L11: Sim | N11: Não | R11: =IF(N11="Sim","Fechado (Total)",IF(N11="Parcial","Fechado (Parcial)",IF(N11="Não","Perdido",IF(N11="Pendente","Pendente",IF(N11="Não precisa no momento","Não Precisa no Momento",IF(L11="Sim","Plano de Tratamento",IF(J11="Não","Não Compareceu",IF(J11="Sim","Compareceu",IF(H11="Não","Perdido",IF(H11="Sim","Consulta Marcada",IF(A11="","","Novo Paciente"))))))))))) -> Perdido | S11: Vai fazer com outro dentista | T11: =IF(A11="","",SUMPRODUCT(($R$2:R11=R11)*($A$2:A11<>""))) -> 4 | U11: =IF(A11="","",R11&"|"&T11) -> Perdido|4 | V11: =IF(G11="","",TEXT(G11,"mm/yyyy")) -> 07/2026 | W11: =IF(P11="","",TEXT(P11,"mm/yyyy")) | X11: =IF(A11="","",IF(OR(R11="Fechado (Total)",R11="Fechado (Parcial)"),"Fechado|"&SUMPRODUCT((($R$2:R11="Fechado (Total)")+($R$2:R11="Fechado (Parcial)"))*($A$2:A11<>"")),"")) | Y11: =IF(A11="","",IF(D11="Indicação",SUMPRODUCT(($D$2:D11="Indicação")*($A$2:A11<>"")),"")) -> 8 | Z11: =IF(Y11="","","Indicacao|"&Y11) -> Indicacao|8 | AA11: =IF(I11="","",TEXT(I11,"mm/yyyy")) -> 07/2026
A12: Gabriela Ribeiro Tostes de Menezes | B12: (12) 98123-9143 | D12: Indicação | E12: Arco Lingual | F12: Mariana | G12: 46210 | H12: Sim | I12: 46212 | J12: Sim | K12: Sim | L12: Sim | M12: 10000 | N12: Não | R12: =IF(N12="Sim","Fechado (Total)",IF(N12="Parcial","Fechado (Parcial)",IF(N12="Não","Perdido",IF(N12="Pendente","Pendente",IF(N12="Não precisa no momento","Não Precisa no Momento",IF(L12="Sim","Plano de Tratamento",IF(J12="Não","Não Compareceu",IF(J12="Sim","Compareceu",IF(H12="Não","Perdido",IF(H12="Sim","Consulta Marcada",IF(A12="","","Novo Paciente"))))))))))) -> Perdido | S12: Vai fazer com outro dentista | T12: =IF(A12="","",SUMPRODUCT(($R$2:R12=R12)*($A$2:A12<>""))) -> 5 | U12: =IF(A12="","",R12&"|"&T12) -> Perdido|5 | V12: =IF(G12="","",TEXT(G12,"mm/yyyy")) -> 07/2026 | W12: =IF(P12="","",TEXT(P12,"mm/yyyy")) | X12: =IF(A12="","",IF(OR(R12="Fechado (Total)",R12="Fechado (Parcial)"),"Fechado|"&SUMPRODUCT((($R$2:R12="Fechado (Total)")+($R$2:R12="Fechado (Parcial)"))*($A$2:A12<>"")),"")) | Y12: =IF(A12="","",IF(D12="Indicação",SUMPRODUCT(($D$2:D12="Indicação")*($A$2:A12<>"")),"")) -> 9 | Z12: =IF(Y12="","","Indicacao|"&Y12) -> Indicacao|9 | AA12: =IF(I12="","",TEXT(I12,"mm/yyyy")) -> 07/2026
A13: Ana Cláudia Ribeiro Marzinetti Dias | B13: (31) 9149-3499 | D13: Indicação | E13: Invisa/aparelho fixo | F13: Mariana | G13: 46213 | H13: Sim | I13: 46216 | J13: Sim | K13: Não | L13: Não | M13: 15000 | N13: Não | R13: =IF(N13="Sim","Fechado (Total)",IF(N13="Parcial","Fechado (Parcial)",IF(N13="Não","Perdido",IF(N13="Pendente","Pendente",IF(N13="Não precisa no momento","Não Precisa no Momento",IF(L13="Sim","Plano de Tratamento",IF(J13="Não","Não Compareceu",IF(J13="Sim","Compareceu",IF(H13="Não","Perdido",IF(H13="Sim","Consulta Marcada",IF(A13="","","Novo Paciente"))))))))))) -> Perdido | S13: Ainda não fez as radiografias / Disse que vai esperar para fazer o tratamento, não vai fazer por agora | T13: =IF(A13="","",SUMPRODUCT(($R$2:R13=R13)*($A$2:A13<>""))) -> 6 | U13: =IF(A13="","",R13&"|"&T13) -> Perdido|6 | V13: =IF(G13="","",TEXT(G13,"mm/yyyy")) -> 07/2026 | W13: =IF(P13="","",TEXT(P13,"mm/yyyy")) | X13: =IF(A13="","",IF(OR(R13="Fechado (Total)",R13="Fechado (Parcial)"),"Fechado|"&SUMPRODUCT((($R$2:R13="Fechado (Total)")+($R$2:R13="Fechado (Parcial)"))*($A$2:A13<>"")),"")) | Y13: =IF(A13="","",IF(D13="Indicação",SUMPRODUCT(($D$2:D13="Indicação")*($A$2:A13<>"")),"")) -> 10 | Z13: =IF(Y13="","","Indicacao|"&Y13) -> Indicacao|10 | AA13: =IF(I13="","",TEXT(I13,"mm/yyyy")) -> 07/2026
A14: Laura Gomes Souto Morato | B14: (31) 99615-3970 | C14: laura.gomesmorato@gmail.com | D14: Indicação | E14: Criança | F14: Mariana | G14: 46205 | H14: Sim | I14: 46211 | J14: Sim | K14: Sim | L14: Sim | M14: 15800 | N14: Sim | O14: 15800 | P14: 46252 | Q14: Retorna mais para frente | R14: =IF(N14="Sim","Fechado (Total)",IF(N14="Parcial","Fechado (Parcial)",IF(N14="Não","Perdido",IF(N14="Pendente","Pendente",IF(N14="Não precisa no momento","Não Precisa no Momento",IF(L14="Sim","Plano de Tratamento",IF(J14="Não","Não Compareceu",IF(J14="Sim","Compareceu",IF(H14="Não","Perdido",IF(H14="Sim","Consulta Marcada",IF(A14="","","Novo Paciente"))))))))))) -> Fechado (Total) | S14: Volta de viagem dia 4 de Agosto | T14: =IF(A14="","",SUMPRODUCT(($R$2:R14=R14)*($A$2:A14<>""))) -> 6 | U14: =IF(A14="","",R14&"|"&T14) -> Fechado (Total)|6 | V14: =IF(G14="","",TEXT(G14,"mm/yyyy")) -> 07/2026 | W14: =IF(P14="","",TEXT(P14,"mm/yyyy")) -> 08/2026 | X14: =IF(A14="","",IF(OR(R14="Fechado (Total)",R14="Fechado (Parcial)"),"Fechado|"&SUMPRODUCT((($R$2:R14="Fechado (Total)")+($R$2:R14="Fechado (Parcial)"))*($A$2:A14<>"")),"")) -> Fechado|6 | Y14: =IF(A14="","",IF(D14="Indicação",SUMPRODUCT(($D$2:D14="Indicação")*($A$2:A14<>"")),"")) -> 11 | Z14: =IF(Y14="","","Indicacao|"&Y14) -> Indicacao|11 | AA14: =IF(I14="","",TEXT(I14,"mm/yyyy")) -> 07/2026
A15: João Gabriel Pinto Coelho Barbosa | B15: (31) 9648-3708 | C15: carolpcsantos@gmail.com | D15: Indicação | E15: Limpeza + avaliação Ortodôntica | F15: Mariana | G15: 46210 | H15: Sim | I15: 46241 | J15: Sim | K15: Sim | L15: Sim | M15: 3800 | N15: Não | R15: =IF(N15="Sim","Fechado (Total)",IF(N15="Parcial","Fechado (Parcial)",IF(N15="Não","Perdido",IF(N15="Pendente","Pendente",IF(N15="Não precisa no momento","Não Precisa no Momento",IF(L15="Sim","Plano de Tratamento",IF(J15="Não","Não Compareceu",IF(J15="Sim","Compareceu",IF(H15="Não","Perdido",IF(H15="Sim","Consulta Marcada",IF(A15="","","Novo Paciente"))))))))))) -> Perdido | T15: =IF(A15="","",SUMPRODUCT(($R$2:R15=R15)*($A$2:A15<>""))) -> 7 | U15: =IF(A15="","",R15&"|"&T15) -> Perdido|7 | V15: =IF(G15="","",TEXT(G15,"mm/yyyy")) -> 07/2026 | W15: =IF(P15="","",TEXT(P15,"mm/yyyy")) | X15: =IF(A15="","",IF(OR(R15="Fechado (Total)",R15="Fechado (Parcial)"),"Fechado|"&SUMPRODUCT((($R$2:R15="Fechado (Total)")+($R$2:R15="Fechado (Parcial)"))*($A$2:A15<>"")),"")) | Y15: =IF(A15="","",IF(D15="Indicação",SUMPRODUCT(($D$2:D15="Indicação")*($A$2:A15<>"")),"")) -> 12 | Z15: =IF(Y15="","","Indicacao|"&Y15) -> Indicacao|12 | AA15: =IF(I15="","",TEXT(I15,"mm/yyyy")) -> 08/2026
A16: Miguel Oliveira Souza | B16: (31) 9131-2159 | C16: lucarmooliveira311@gmail.com | D16: Indicação | E16: Aparelho Fixo Metálico | F16: Natalia | G16: 46203 | H16: Sim | I16: 46217 | J16: Sim | K16: Sim | L16: Sim | M16: 2000 | N16: Sim | O16: 1941 | P16: 46217 | R16: =IF(N16="Sim","Fechado (Total)",IF(N16="Parcial","Fechado (Parcial)",IF(N16="Não","Perdido",IF(N16="Pendente","Pendente",IF(N16="Não precisa no momento","Não Precisa no Momento",IF(L16="Sim","Plano de Tratamento",IF(J16="Não","Não Compareceu",IF(J16="Sim","Compareceu",IF(H16="Não","Perdido",IF(H16="Sim","Consulta Marcada",IF(A16="","","Novo Paciente"))))))))))) -> Fechado (Total) | T16: =IF(A16="","",SUMPRODUCT(($R$2:R16=R16)*($A$2:A16<>""))) -> 7 | U16: =IF(A16="","",R16&"|"&T16) -> Fechado (Total)|7 | V16: =IF(G16="","",TEXT(G16,"mm/yyyy")) -> 06/2026 | W16: =IF(P16="","",TEXT(P16,"mm/yyyy")) -> 07/2026 | X16: =IF(A16="","",IF(OR(R16="Fechado (Total)",R16="Fechado (Parcial)"),"Fechado|"&SUMPRODUCT((($R$2:R16="Fechado (Total)")+($R$2:R16="Fechado (Parcial)"))*($A$2:A16<>"")),"")) -> Fechado|7 | Y16: =IF(A16="","",IF(D16="Indicação",SUMPRODUCT(($D$2:D16="Indicação")*($A$2:A16<>"")),"")) -> 13 | Z16: =IF(Y16="","","Indicacao|"&Y16) -> Indicacao|13 | AA16: =IF(I16="","",TEXT(I16,"mm/yyyy")) -> 07/2026
A17: Felipe da Cunha Pereira Rocha Lacerda | B17: (31) 9973-7100 | D17: Indicação | E17: Invisalign | F17: Natalia | G17: 46198 | H17: Sim | I17: 46218 | J17: Sim | K17: Sim | L17: Sim | M17: 11500 | N17: Pendente | R17: =IF(N17="Sim","Fechado (Total)",IF(N17="Parcial","Fechado (Parcial)",IF(N17="Não","Perdido",IF(N17="Pendente","Pendente",IF(N17="Não precisa no momento","Não Precisa no Momento",IF(L17="Sim","Plano de Tratamento",IF(J17="Não","Não Compareceu",IF(J17="Sim","Compareceu",IF(H17="Não","Perdido",IF(H17="Sim","Consulta Marcada",IF(A17="","","Novo Paciente"))))))))))) -> Pendente | T17: =IF(A17="","",SUMPRODUCT(($R$2:R17=R17)*($A$2:A17<>""))) -> 2 | U17: =IF(A17="","",R17&"|"&T17) -> Pendente|2 | V17: =IF(G17="","",TEXT(G17,"mm/yyyy")) -> 06/2026 | W17: =IF(P17="","",TEXT(P17,"mm/yyyy")) | X17: =IF(A17="","",IF(OR(R17="Fechado (Total)",R17="Fechado (Parcial)"),"Fechado|"&SUMPRODUCT((($R$2:R17="Fechado (Total)")+($R$2:R17="Fechado (Parcial)"))*($A$2:A17<>"")),"")) | Y17: =IF(A17="","",IF(D17="Indicação",SUMPRODUCT(($D$2:D17="Indicação")*($A$2:A17<>"")),"")) -> 14 | Z17: =IF(Y17="","","Indicacao|"&Y17) -> Indicacao|14 | AA17: =IF(I17="","",TEXT(I17,"mm/yyyy")) -> 07/2026
A18: Gabriel da Rocha Bastos | B18: (31) 8895-5842 | D18: Indicação | E18: Fixo | F18: Natalia | G18: 46213 | H18: Sim | I18: 46218 | J18: Sim | K18: Sim | R18: =IF(N18="Sim","Fechado (Total)",IF(N18="Parcial","Fechado (Parcial)",IF(N18="Não","Perdido",IF(N18="Pendente","Pendente",IF(N18="Não precisa no momento","Não Precisa no Momento",IF(L18="Sim","Plano de Tratamento",IF(J18="Não","Não Compareceu",IF(J18="Sim","Compareceu",IF(H18="Não","Perdido",IF(H18="Sim","Consulta Marcada",IF(A18="","","Novo Paciente"))))))))))) -> Compareceu | T18: =IF(A18="","",SUMPRODUCT(($R$2:R18=R18)*($A$2:A18<>""))) -> 1 | U18: =IF(A18="","",R18&"|"&T18) -> Compareceu|1 | V18: =IF(G18="","",TEXT(G18,"mm/yyyy")) -> 07/2026 | W18: =IF(P18="","",TEXT(P18,"mm/yyyy")) | X18: =IF(A18="","",IF(OR(R18="Fechado (Total)",R18="Fechado (Parcial)"),"Fechado|"&SUMPRODUCT((($R$2:R18="Fechado (Total)")+($R$2:R18="Fechado (Parcial)"))*($A$2:A18<>"")),"")) | Y18: =IF(A18="","",IF(D18="Indicação",SUMPRODUCT(($D$2:D18="Indicação")*($A$2:A18<>"")),"")) -> 15 | Z18: =IF(Y18="","","Indicacao|"&Y18) -> Indicacao|15 | AA18: =IF(I18="","",TEXT(I18,"mm/yyyy")) -> 07/2026
A19: Fernando Ferreira Medeiros | B19: (31) 9977-8270 | D19: Indicação | E19: Invisalign | F19: Natalia | G19: 46162 | H19: Sim | I19: 46199 | J19: Sim | K19: Sim | L19: Sim | M19: 13000 | N19: Pendente | R19: =IF(N19="Sim","Fechado (Total)",IF(N19="Parcial","Fechado (Parcial)",IF(N19="Não","Perdido",IF(N19="Pendente","Pendente",IF(N19="Não precisa no momento","Não Precisa no Momento",IF(L19="Sim","Plano de Tratamento",IF(J19="Não","Não Compareceu",IF(J19="Sim","Compareceu",IF(H19="Não","Perdido",IF(H19="Sim","Consulta Marcada",IF(A19="","","Novo Paciente"))))))))))) -> Pendente | S19: ainda não nos deu retorna a respeito | T19: =IF(A19="","",SUMPRODUCT(($R$2:R19=R19)*($A$2:A19<>""))) -> 3 | U19: =IF(A19="","",R19&"|"&T19) -> Pendente|3 | V19: =IF(G19="","",TEXT(G19,"mm/yyyy")) -> 05/2026 | W19: =IF(P19="","",TEXT(P19,"mm/yyyy")) | X19: =IF(A19="","",IF(OR(R19="Fechado (Total)",R19="Fechado (Parcial)"),"Fechado|"&SUMPRODUCT((($R$2:R19="Fechado (Total)")+($R$2:R19="Fechado (Parcial)"))*($A$2:A19<>"")),"")) | Y19: =IF(A19="","",IF(D19="Indicação",SUMPRODUCT(($D$2:D19="Indicação")*($A$2:A19<>"")),"")) -> 16 | Z19: =IF(Y19="","","Indicacao|"&Y19) -> Indicacao|16 | AA19: =IF(I19="","",TEXT(I19,"mm/yyyy")) -> 06/2026
A20: Lavinia Ferreira de La Fuente | B20: (31) 99427-1121 | C20: nataliaedanilo@hotmail.com | D20: Indicação | E20: Criança | F20: Mariana | G20: 46254 | H20: Sim | I20: 46225 | J20: Sim | K20: Sim | L20: Sim | M20: 0 | N20: Sim | O20: 0 | P20: 46231 | R20: =IF(N20="Sim","Fechado (Total)",IF(N20="Parcial","Fechado (Parcial)",IF(N20="Não","Perdido",IF(N20="Pendente","Pendente",IF(N20="Não precisa no momento","Não Precisa no Momento",IF(L20="Sim","Plano de Tratamento",IF(J20="Não","Não Compareceu",IF(J20="Sim","Compareceu",IF(H20="Não","Perdido",IF(H20="Sim","Consulta Marcada",IF(A20="","","Novo Paciente"))))))))))) -> Fechado (Total) | S20: Não foi cobrado | T20: =IF(A20="","",SUMPRODUCT(($R$2:R20=R20)*($A$2:A20<>""))) -> 8 | U20: =IF(A20="","",R20&"|"&T20) -> Fechado (Total)|8 | V20: =IF(G20="","",TEXT(G20,"mm/yyyy")) -> 08/2026 | W20: =IF(P20="","",TEXT(P20,"mm/yyyy")) -> 07/2026 | X20: =IF(A20="","",IF(OR(R20="Fechado (Total)",R20="Fechado (Parcial)"),"Fechado|"&SUMPRODUCT((($R$2:R20="Fechado (Total)")+($R$2:R20="Fechado (Parcial)"))*($A$2:A20<>"")),"")) -> Fechado|8 | Y20: =IF(A20="","",IF(D20="Indicação",SUMPRODUCT(($D$2:D20="Indicação")*($A$2:A20<>"")),"")) -> 17 | Z20: =IF(Y20="","","Indicacao|"&Y20) -> Indicacao|17 | AA20: =IF(I20="","",TEXT(I20,"mm/yyyy")) -> 07/2026
A21: Vitor Mesquita Carlos Gomes | B21: (31) 8200-2267 | C21: vitormesquita253@gmail.com | D21: Indicação | E21: Invisalign | F21: Mariana | G21: 46226 | H21: Sim | I21: 46231 | J21: Sim | K21: Sim | L21: Sim | M21: 6000 | N21: Sim | O21: 5383 | P21: 46231 | R21: =IF(N21="Sim","Fechado (Total)",IF(N21="Parcial","Fechado (Parcial)",IF(N21="Não","Perdido",IF(N21="Pendente","Pendente",IF(N21="Não precisa no momento","Não Precisa no Momento",IF(L21="Sim","Plano de Tratamento",IF(J21="Não","Não Compareceu",IF(J21="Sim","Compareceu",IF(H21="Não","Perdido",IF(H21="Sim","Consulta Marcada",IF(A21="","","Novo Paciente"))))))))))) -> Fechado (Total) | T21: =IF(A21="","",SUMPRODUCT(($R$2:R21=R21)*($A$2:A21<>""))) -> 9 | U21: =IF(A21="","",R21&"|"&T21) -> Fechado (Total)|9 | V21: =IF(G21="","",TEXT(G21,"mm/yyyy")) -> 07/2026 | W21: =IF(P21="","",TEXT(P21,"mm/yyyy")) -> 07/2026 | X21: =IF(A21="","",IF(OR(R21="Fechado (Total)",R21="Fechado (Parcial)"),"Fechado|"&SUMPRODUCT((($R$2:R21="Fechado (Total)")+($R$2:R21="Fechado (Parcial)"))*($A$2:A21<>"")),"")) -> Fechado|9 | Y21: =IF(A21="","",IF(D21="Indicação",SUMPRODUCT(($D$2:D21="Indicação")*($A$2:A21<>"")),"")) -> 18 | Z21: =IF(Y21="","","Indicacao|"&Y21) -> Indicacao|18 | AA21: =IF(I21="","",TEXT(I21,"mm/yyyy")) -> 07/2026
A22: Monica Maria Alves Pereira | B22: (31) 9896-3333 | D22: Indicação | E22: Invisalign | F22: Mariana | G22: 46233 | H22: Sim | I22: 46234 | J22: Sim | K22: Sim | L22: Sim | M22: 15800 | N22: Sim | O22: 15800 | P22: 46245 | R22: =IF(N22="Sim","Fechado (Total)",IF(N22="Parcial","Fechado (Parcial)",IF(N22="Não","Perdido",IF(N22="Pendente","Pendente",IF(N22="Não precisa no momento","Não Precisa no Momento",IF(L22="Sim","Plano de Tratamento",IF(J22="Não","Não Compareceu",IF(J22="Sim","Compareceu",IF(H22="Não","Perdido",IF(H22="Sim","Consulta Marcada",IF(A22="","","Novo Paciente"))))))))))) -> Fechado (Total) | T22: =IF(A22="","",SUMPRODUCT(($R$2:R22=R22)*($A$2:A22<>""))) -> 10 | U22: =IF(A22="","",R22&"|"&T22) -> Fechado (Total)|10 | V22: =IF(G22="","",TEXT(G22,"mm/yyyy")) -> 07/2026 | W22: =IF(P22="","",TEXT(P22,"mm/yyyy")) -> 08/2026 | X22: =IF(A22="","",IF(OR(R22="Fechado (Total)",R22="Fechado (Parcial)"),"Fechado|"&SUMPRODUCT((($R$2:R22="Fechado (Total)")+($R$2:R22="Fechado (Parcial)"))*($A$2:A22<>"")),"")) -> Fechado|10 | Y22: =IF(A22="","",IF(D22="Indicação",SUMPRODUCT(($D$2:D22="Indicação")*($A$2:A22<>"")),"")) -> 19 | Z22: =IF(Y22="","","Indicacao|"&Y22) -> Indicacao|19 | AA22: =IF(I22="","",TEXT(I22,"mm/yyyy")) -> 07/2026
A23: Serena Catão de Miranda | B23: (31) 99909-2329 | C23: marcilioadvocacia@gmail.com | D23: já é paciente | E23: Invisalign | F23: Natalia | G23: 46227 | H23: Sim | I23: 46238 | J23: Sim | K23: Sim | L23: Sim | M23: 16000 | N23: Pendente | R23: =IF(N23="Sim","Fechado (Total)",IF(N23="Parcial","Fechado (Parcial)",IF(N23="Não","Perdido",IF(N23="Pendente","Pendente",IF(N23="Não precisa no momento","Não Precisa no Momento",IF(L23="Sim","Plano de Tratamento",IF(J23="Não","Não Compareceu",IF(J23="Sim","Compareceu",IF(H23="Não","Perdido",IF(H23="Sim","Consulta Marcada",IF(A23="","","Novo Paciente"))))))))))) -> Pendente | T23: =IF(A23="","",SUMPRODUCT(($R$2:R23=R23)*($A$2:A23<>""))) -> 4 | U23: =IF(A23="","",R23&"|"&T23) -> Pendente|4 | V23: =IF(G23="","",TEXT(G23,"mm/yyyy")) -> 07/2026 | W23: =IF(P23="","",TEXT(P23,"mm/yyyy")) | X23: =IF(A23="","",IF(OR(R23="Fechado (Total)",R23="Fechado (Parcial)"),"Fechado|"&SUMPRODUCT((($R$2:R23="Fechado (Total)")+($R$2:R23="Fechado (Parcial)"))*($A$2:A23<>"")),"")) | Y23: =IF(A23="","",IF(D23="Indicação",SUMPRODUCT(($D$2:D23="Indicação")*($A$2:A23<>"")),"")) | Z23: =IF(Y23="","","Indicacao|"&Y23) | AA23: =IF(I23="","",TEXT(I23,"mm/yyyy")) -> 08/2026
A24: Camila de Almeida Teixeira Nominato | B24: (31) 99946-7948 | C24: teixeira.caa@gmail.com | D24: já é paciente | E24: Invisalign | F24: Mariana | G24: 46264 | H24: Sim | I24: 46265 | J24: Sim | K24: Não | L24: Sim | M24: 13500 | N24: Sim | O24: 11743.35 | P24: 46265 | R24: =IF(N24="Sim","Fechado (Total)",IF(N24="Parcial","Fechado (Parcial)",IF(N24="Não","Perdido",IF(N24="Pendente","Pendente",IF(N24="Não precisa no momento","Não Precisa no Momento",IF(L24="Sim","Plano de Tratamento",IF(J24="Não","Não Compareceu",IF(J24="Sim","Compareceu",IF(H24="Não","Perdido",IF(H24="Sim","Consulta Marcada",IF(A24="","","Novo Paciente"))))))))))) -> Fechado (Total) | T24: =IF(A24="","",SUMPRODUCT(($R$2:R24=R24)*($A$2:A24<>""))) -> 11 | U24: =IF(A24="","",R24&"|"&T24) -> Fechado (Total)|11 | V24: =IF(G24="","",TEXT(G24,"mm/yyyy")) -> 08/2026 | W24: =IF(P24="","",TEXT(P24,"mm/yyyy")) -> 08/2026 | X24: =IF(A24="","",IF(OR(R24="Fechado (Total)",R24="Fechado (Parcial)"),"Fechado|"&SUMPRODUCT((($R$2:R24="Fechado (Total)")+($R$2:R24="Fechado (Parcial)"))*($A$2:A24<>"")),"")) -> Fechado|11 | Y24: =IF(A24="","",IF(D24="Indicação",SUMPRODUCT(($D$2:D24="Indicação")*($A$2:A24<>"")),"")) | Z24: =IF(Y24="","","Indicacao|"&Y24) | AA24: =IF(I24="","",TEXT(I24,"mm/yyyy")) -> 08/2026
A25: João Gabriel Cardoso de Oliveira | B25: (31) 9810-9624 | C25: carolinadacruzcardoso@gmail.com | D25: já é paciente | E25: Criança | F25: Mariana | G25: 45511 | R25: =IF(N25="Sim","Fechado (Total)",IF(N25="Parcial","Fechado (Parcial)",IF(N25="Não","Perdido",IF(N25="Pendente","Pendente",IF(N25="Não precisa no momento","Não Precisa no Momento",IF(L25="Sim","Plano de Tratamento",IF(J25="Não","Não Compareceu",IF(J25="Sim","Compareceu",IF(H25="Não","Perdido",IF(H25="Sim","Consulta Marcada",IF(A25="","","Novo Paciente"))))))))))) -> Novo Paciente | T25: =IF(A25="","",SUMPRODUCT(($R$2:R25=R25)*($A$2:A25<>""))) -> 1 | U25: =IF(A25="","",R25&"|"&T25) -> Novo Paciente|1 | V25: =IF(G25="","",TEXT(G25,"mm/yyyy")) -> 08/2024 | W25: =IF(P25="","",TEXT(P25,"mm/yyyy")) | X25: =IF(A25="","",IF(OR(R25="Fechado (Total)",R25="Fechado (Parcial)"),"Fechado|"&SUMPRODUCT((($R$2:R25="Fechado (Total)")+($R$2:R25="Fechado (Parcial)"))*($A$2:A25<>"")),"")) | Y25: =IF(A25="","",IF(D25="Indicação",SUMPRODUCT(($D$2:D25="Indicação")*($A$2:A25<>"")),"")) | Z25: =IF(Y25="","","Indicacao|"&Y25) | AA25: =IF(I25="","",TEXT(I25,"mm/yyyy"))
A26: Christiane Alves Esteves Diniz Guerra | B26: (917) 570-1155 | D26: Indicação | E26: Invisalign | F26: Mariana | G26: 46153 | H26: Sim | I26: 46227 | J26: Sim | K26: Sim | L26: Sim | M26: 12000 | N26: Sim | O26: 10000 | P26: 46240 | R26: =IF(N26="Sim","Fechado (Total)",IF(N26="Parcial","Fechado (Parcial)",IF(N26="Não","Perdido",IF(N26="Pendente","Pendente",IF(N26="Não precisa no momento","Não Precisa no Momento",IF(L26="Sim","Plano de Tratamento",IF(J26="Não","Não Compareceu",IF(J26="Sim","Compareceu",IF(H26="Não","Perdido",IF(H26="Sim","Consulta Marcada",IF(A26="","","Novo Paciente"))))))))))) -> Fechado (Total) | S26: Vai pagar 6mil em Agosto e 4mil em Novembro | T26: =IF(A26="","",SUMPRODUCT(($R$2:R26=R26)*($A$2:A26<>""))) -> 12 | U26: =IF(A26="","",R26&"|"&T26) -> Fechado (Total)|12 | V26: =IF(G26="","",TEXT(G26,"mm/yyyy")) -> 05/2026 | W26: =IF(P26="","",TEXT(P26,"mm/yyyy")) -> 08/2026 | X26: =IF(A26="","",IF(OR(R26="Fechado (Total)",R26="Fechado (Parcial)"),"Fechado|"&SUMPRODUCT((($R$2:R26="Fechado (Total)")+($R$2:R26="Fechado (Parcial)"))*($A$2:A26<>"")),"")) -> Fechado|12 | Y26: =IF(A26="","",IF(D26="Indicação",SUMPRODUCT(($D$2:D26="Indicação")*($A$2:A26<>"")),"")) -> 20 | Z26: =IF(Y26="","","Indicacao|"&Y26) -> Indicacao|20 | AA26: =IF(I26="","",TEXT(I26,"mm/yyyy")) -> 07/2026
A27: Kezia Cristina Teodoro dos Santos | B27: (31) 9429-4140 | C27: keziac_santos@yahoo.com.br | D27: Indicação | E27: Invisalign / Fixo | F27: Natalia | G27: 46238 | H27: Sim | I27: 46239 | J27: Sim | K27: Sim | L27: Sim | M27: 14000 | N27: Pendente | R27: =IF(N27="Sim","Fechado (Total)",IF(N27="Parcial","Fechado (Parcial)",IF(N27="Não","Perdido",IF(N27="Pendente","Pendente",IF(N27="Não precisa no momento","Não Precisa no Momento",IF(L27="Sim","Plano de Tratamento",IF(J27="Não","Não Compareceu",IF(J27="Sim","Compareceu",IF(H27="Não","Perdido",IF(H27="Sim","Consulta Marcada",IF(A27="","","Novo Paciente"))))))))))) -> Pendente | T27: =IF(A27="","",SUMPRODUCT(($R$2:R27=R27)*($A$2:A27<>""))) -> 5 | U27: =IF(A27="","",R27&"|"&T27) -> Pendente|5 | V27: =IF(G27="","",TEXT(G27,"mm/yyyy")) -> 08/2026 | W27: =IF(P27="","",TEXT(P27,"mm/yyyy")) | X27: =IF(A27="","",IF(OR(R27="Fechado (Total)",R27="Fechado (Parcial)"),"Fechado|"&SUMPRODUCT((($R$2:R27="Fechado (Total)")+($R$2:R27="Fechado (Parcial)"))*($A$2:A27<>"")),"")) | Y27: =IF(A27="","",IF(D27="Indicação",SUMPRODUCT(($D$2:D27="Indicação")*($A$2:A27<>"")),"")) -> 21 | Z27: =IF(Y27="","","Indicacao|"&Y27) -> Indicacao|21 | AA27: =IF(I27="","",TEXT(I27,"mm/yyyy")) -> 08/2026
A28: Izabela Maia Resende | B28: (31) 9937-7621 | C28: marielasoutomaia@gmail.com | D28: Indicação | E28: Invisalign | F28: Natalia | G28: 46238 | H28: Sim | I28: 46239 | J28: Sim | K28: Sim | L28: Sim | M28: 16200 | N28: Sim | O28: 16200 | P28: 46245 | R28: =IF(N28="Sim","Fechado (Total)",IF(N28="Parcial","Fechado (Parcial)",IF(N28="Não","Perdido",IF(N28="Pendente","Pendente",IF(N28="Não precisa no momento","Não Precisa no Momento",IF(L28="Sim","Plano de Tratamento",IF(J28="Não","Não Compareceu",IF(J28="Sim","Compareceu",IF(H28="Não","Perdido",IF(H28="Sim","Consulta Marcada",IF(A28="","","Novo Paciente"))))))))))) -> Fechado (Total) | T28: =IF(A28="","",SUMPRODUCT(($R$2:R28=R28)*($A$2:A28<>""))) -> 13 | U28: =IF(A28="","",R28&"|"&T28) -> Fechado (Total)|13 | V28: =IF(G28="","",TEXT(G28,"mm/yyyy")) -> 08/2026 | W28: =IF(P28="","",TEXT(P28,"mm/yyyy")) -> 08/2026 | X28: =IF(A28="","",IF(OR(R28="Fechado (Total)",R28="Fechado (Parcial)"),"Fechado|"&SUMPRODUCT((($R$2:R28="Fechado (Total)")+($R$2:R28="Fechado (Parcial)"))*($A$2:A28<>"")),"")) -> Fechado|13 | Y28: =IF(A28="","",IF(D28="Indicação",SUMPRODUCT(($D$2:D28="Indicação")*($A$2:A28<>"")),"")) -> 22 | Z28: =IF(Y28="","","Indicacao|"&Y28) -> Indicacao|22 | AA28: =IF(I28="","",TEXT(I28,"mm/yyyy")) -> 08/2026
A29: Eduardo Lamaita Figueiredo | B29: (31) 8264-9025 | C29: lu_lamaita@hotmail.com | D29: Indicação | E29: Criança | F29: Natalia | G29: 46239 | H29: Sim | I29: 46246 | J29: Sim | K29: Sim | L29: Sim | N29: Pendente | R29: =IF(N29="Sim","Fechado (Total)",IF(N29="Parcial","Fechado (Parcial)",IF(N29="Não","Perdido",IF(N29="Pendente","Pendente",IF(N29="Não precisa no momento","Não Precisa no Momento",IF(L29="Sim","Plano de Tratamento",IF(J29="Não","Não Compareceu",IF(J29="Sim","Compareceu",IF(H29="Não","Perdido",IF(H29="Sim","Consulta Marcada",IF(A29="","","Novo Paciente"))))))))))) -> Pendente | T29: =IF(A29="","",SUMPRODUCT(($R$2:R29=R29)*($A$2:A29<>""))) -> 6 | U29: =IF(A29="","",R29&"|"&T29) -> Pendente|6 | V29: =IF(G29="","",TEXT(G29,"mm/yyyy")) -> 08/2026 | W29: =IF(P29="","",TEXT(P29,"mm/yyyy")) | X29: =IF(A29="","",IF(OR(R29="Fechado (Total)",R29="Fechado (Parcial)"),"Fechado|"&SUMPRODUCT((($R$2:R29="Fechado (Total)")+($R$2:R29="Fechado (Parcial)"))*($A$2:A29<>"")),"")) | Y29: =IF(A29="","",IF(D29="Indicação",SUMPRODUCT(($D$2:D29="Indicação")*($A$2:A29<>"")),"")) -> 23 | Z29: =IF(Y29="","","Indicacao|"&Y29) -> Indicacao|23 | AA29: =IF(I29="","",TEXT(I29,"mm/yyyy")) -> 08/2026
A30: Flavia Mendonça Pinheiro de Melo | B30: (31) 9988-8581 | D30: Indicação | E30: Invisalign | F30: Mariana | G30: 46146 | H30: Sim | I30: 46247 | J30: Sim | K30: Não | L30: Sim | M30: 10500 | N30: Pendente | R30: =IF(N30="Sim","Fechado (Total)",IF(N30="Parcial","Fechado (Parcial)",IF(N30="Não","Perdido",IF(N30="Pendente","Pendente",IF(N30="Não precisa no momento","Não Precisa no Momento",IF(L30="Sim","Plano de Tratamento",IF(J30="Não","Não Compareceu",IF(J30="Sim","Compareceu",IF(H30="Não","Perdido",IF(H30="Sim","Consulta Marcada",IF(A30="","","Novo Paciente"))))))))))) -> Pendente | T30: =IF(A30="","",SUMPRODUCT(($R$2:R30=R30)*($A$2:A30<>""))) -> 7 | U30: =IF(A30="","",R30&"|"&T30) -> Pendente|7 | V30: =IF(G30="","",TEXT(G30,"mm/yyyy")) -> 05/2026 | W30: =IF(P30="","",TEXT(P30,"mm/yyyy")) | X30: =IF(A30="","",IF(OR(R30="Fechado (Total)",R30="Fechado (Parcial)"),"Fechado|"&SUMPRODUCT((($R$2:R30="Fechado (Total)")+($R$2:R30="Fechado (Parcial)"))*($A$2:A30<>"")),"")) | Y30: =IF(A30="","",IF(D30="Indicação",SUMPRODUCT(($D$2:D30="Indicação")*($A$2:A30<>"")),"")) -> 24 | Z30: =IF(Y30="","","Indicacao|"&Y30) -> Indicacao|24 | AA30: =IF(I30="","",TEXT(I30,"mm/yyyy")) -> 08/2026
A31: Gabriela Mendonça Pinheiro de Melo | B31: (31) 9988-8581 | D31: Indicação | F31: Mariana | G31: 46146 | H31: Sim | I31: 46251 | J31: Não | R31: =IF(N31="Sim","Fechado (Total)",IF(N31="Parcial","Fechado (Parcial)",IF(N31="Não","Perdido",IF(N31="Pendente","Pendente",IF(N31="Não precisa no momento","Não Precisa no Momento",IF(L31="Sim","Plano de Tratamento",IF(J31="Não","Não Compareceu",IF(J31="Sim","Compareceu",IF(H31="Não","Perdido",IF(H31="Sim","Consulta Marcada",IF(A31="","","Novo Paciente"))))))))))) -> Não Compareceu | T31: =IF(A31="","",SUMPRODUCT(($R$2:R31=R31)*($A$2:A31<>""))) -> 1 | U31: =IF(A31="","",R31&"|"&T31) -> Não Compareceu|1 | V31: =IF(G31="","",TEXT(G31,"mm/yyyy")) -> 05/2026 | W31: =IF(P31="","",TEXT(P31,"mm/yyyy")) | X31: =IF(A31="","",IF(OR(R31="Fechado (Total)",R31="Fechado (Parcial)"),"Fechado|"&SUMPRODUCT((($R$2:R31="Fechado (Total)")+($R$2:R31="Fechado (Parcial)"))*($A$2:A31<>"")),"")) | Y31: =IF(A31="","",IF(D31="Indicação",SUMPRODUCT(($D$2:D31="Indicação")*($A$2:A31<>"")),"")) -> 25 | Z31: =IF(Y31="","","Indicacao|"&Y31) -> Indicacao|25 | AA31: =IF(I31="","",TEXT(I31,"mm/yyyy")) -> 08/2026
A32: Helena Barcelos Avelar | B32: (31) 9302-5504 | D32: Indicação | E32: Fixo | F32: Natalia | H32: Sim | I32: 46255 | J32: Sim | K32: Não | L32: Sim | N32: Pendente | R32: =IF(N32="Sim","Fechado (Total)",IF(N32="Parcial","Fechado (Parcial)",IF(N32="Não","Perdido",IF(N32="Pendente","Pendente",IF(N32="Não precisa no momento","Não Precisa no Momento",IF(L32="Sim","Plano de Tratamento",IF(J32="Não","Não Compareceu",IF(J32="Sim","Compareceu",IF(H32="Não","Perdido",IF(H32="Sim","Consulta Marcada",IF(A32="","","Novo Paciente"))))))))))) -> Pendente | T32: =IF(A32="","",SUMPRODUCT(($R$2:R32=R32)*($A$2:A32<>""))) -> 8 | U32: =IF(A32="","",R32&"|"&T32) -> Pendente|8 | V32: =IF(G32="","",TEXT(G32,"mm/yyyy")) | W32: =IF(P32="","",TEXT(P32,"mm/yyyy")) | X32: =IF(A32="","",IF(OR(R32="Fechado (Total)",R32="Fechado (Parcial)"),"Fechado|"&SUMPRODUCT((($R$2:R32="Fechado (Total)")+($R$2:R32="Fechado (Parcial)"))*($A$2:A32<>"")),"")) | Y32: =IF(A32="","",IF(D32="Indicação",SUMPRODUCT(($D$2:D32="Indicação")*($A$2:A32<>"")),"")) -> 26 | Z32: =IF(Y32="","","Indicacao|"&Y32) -> Indicacao|26 | AA32: =IF(I32="","",TEXT(I32,"mm/yyyy")) -> 08/2026
A33: Joaquim Manduca Campos | B33: (31) 9911-5338 | C33: mariedmanduca@gmail.com | D33: Indicação | E33: Criança | G33: 46197 | H33: Sim | I33: 46252 | J33: Sim | K33: Não | R33: =IF(N33="Sim","Fechado (Total)",IF(N33="Parcial","Fechado (Parcial)",IF(N33="Não","Perdido",IF(N33="Pendente","Pendente",IF(N33="Não precisa no momento","Não Precisa no Momento",IF(L33="Sim","Plano de Tratamento",IF(J33="Não","Não Compareceu",IF(J33="Sim","Compareceu",IF(H33="Não","Perdido",IF(H33="Sim","Consulta Marcada",IF(A33="","","Novo Paciente"))))))))))) -> Compareceu | T33: =IF(A33="","",SUMPRODUCT(($R$2:R33=R33)*($A$2:A33<>""))) -> 2 | U33: =IF(A33="","",R33&"|"&T33) -> Compareceu|2 | V33: =IF(G33="","",TEXT(G33,"mm/yyyy")) -> 06/2026 | W33: =IF(P33="","",TEXT(P33,"mm/yyyy")) | X33: =IF(A33="","",IF(OR(R33="Fechado (Total)",R33="Fechado (Parcial)"),"Fechado|"&SUMPRODUCT((($R$2:R33="Fechado (Total)")+($R$2:R33="Fechado (Parcial)"))*($A$2:A33<>"")),"")) | Y33: =IF(A33="","",IF(D33="Indicação",SUMPRODUCT(($D$2:D33="Indicação")*($A$2:A33<>"")),"")) -> 27 | Z33: =IF(Y33="","","Indicacao|"&Y33) -> Indicacao|27 | AA33: =IF(I33="","",TEXT(I33,"mm/yyyy")) -> 08/2026
A34: Maried Guimarães Manduca Campos | B34: (31) 9911-5338 | C34: mariedmanduca@gmail.com | D34: Indicação | E34: Fixo | G34: 46197 | H34: Sim | I34: 46251 | J34: Sim | K34: Não | R34: =IF(N34="Sim","Fechado (Total)",IF(N34="Parcial","Fechado (Parcial)",IF(N34="Não","Perdido",IF(N34="Pendente","Pendente",IF(N34="Não precisa no momento","Não Precisa no Momento",IF(L34="Sim","Plano de Tratamento",IF(J34="Não","Não Compareceu",IF(J34="Sim","Compareceu",IF(H34="Não","Perdido",IF(H34="Sim","Consulta Marcada",IF(A34="","","Novo Paciente"))))))))))) -> Compareceu | T34: =IF(A34="","",SUMPRODUCT(($R$2:R34=R34)*($A$2:A34<>""))) -> 3 | U34: =IF(A34="","",R34&"|"&T34) -> Compareceu|3 | V34: =IF(G34="","",TEXT(G34,"mm/yyyy")) -> 06/2026 | W34: =IF(P34="","",TEXT(P34,"mm/yyyy")) | X34: =IF(A34="","",IF(OR(R34="Fechado (Total)",R34="Fechado (Parcial)"),"Fechado|"&SUMPRODUCT((($R$2:R34="Fechado (Total)")+($R$2:R34="Fechado (Parcial)"))*($A$2:A34<>"")),"")) | Y34: =IF(A34="","",IF(D34="Indicação",SUMPRODUCT(($D$2:D34="Indicação")*($A$2:A34<>"")),"")) -> 28 | Z34: =IF(Y34="","","Indicacao|"&Y34) -> Indicacao|28 | AA34: =IF(I34="","",TEXT(I34,"mm/yyyy")) -> 08/2026
A35: Otávio Rangel Ferreira | B35: (31) 8873-5003 | C35: kellyurirangel@gmail.com | D35: já é paciente | G35: 46254 | H35: Sim | I35: 46252 | J35: Sim | K35: Sim | L35: Sim | M35: 4000 | N35: Sim | O35: 4000 | P35: 46252 | R35: =IF(N35="Sim","Fechado (Total)",IF(N35="Parcial","Fechado (Parcial)",IF(N35="Não","Perdido",IF(N35="Pendente","Pendente",IF(N35="Não precisa no momento","Não Precisa no Momento",IF(L35="Sim","Plano de Tratamento",IF(J35="Não","Não Compareceu",IF(J35="Sim","Compareceu",IF(H35="Não","Perdido",IF(H35="Sim","Consulta Marcada",IF(A35="","","Novo Paciente"))))))))))) -> Fechado (Total) | T35: =IF(A35="","",SUMPRODUCT(($R$2:R35=R35)*($A$2:A35<>""))) -> 14 | U35: =IF(A35="","",R35&"|"&T35) -> Fechado (Total)|14 | V35: =IF(G35="","",TEXT(G35,"mm/yyyy")) -> 08/2026 | W35: =IF(P35="","",TEXT(P35,"mm/yyyy")) -> 08/2026 | X35: =IF(A35="","",IF(OR(R35="Fechado (Total)",R35="Fechado (Parcial)"),"Fechado|"&SUMPRODUCT((($R$2:R35="Fechado (Total)")+($R$2:R35="Fechado (Parcial)"))*($A$2:A35<>"")),"")) -> Fechado|14 | Y35: =IF(A35="","",IF(D35="Indicação",SUMPRODUCT(($D$2:D35="Indicação")*($A$2:A35<>"")),"")) | Z35: =IF(Y35="","","Indicacao|"&Y35) | AA35: =IF(I35="","",TEXT(I35,"mm/yyyy")) -> 08/2026
A36: Maria Carolina Silva Dornelas | B36: (31) 9775-9100 | D36: já é paciente | G36: 46244 | H36: Sim | I36: 46252 | J36: Sim | K36: Sim | L36: Sim | M36: 2000 | N36: Não | R36: =IF(N36="Sim","Fechado (Total)",IF(N36="Parcial","Fechado (Parcial)",IF(N36="Não","Perdido",IF(N36="Pendente","Pendente",IF(N36="Não precisa no momento","Não Precisa no Momento",IF(L36="Sim","Plano de Tratamento",IF(J36="Não","Não Compareceu",IF(J36="Sim","Compareceu",IF(H36="Não","Perdido",IF(H36="Sim","Consulta Marcada",IF(A36="","","Novo Paciente"))))))))))) -> Perdido | T36: =IF(A36="","",SUMPRODUCT(($R$2:R36=R36)*($A$2:A36<>""))) -> 8 | U36: =IF(A36="","",R36&"|"&T36) -> Perdido|8 | V36: =IF(G36="","",TEXT(G36,"mm/yyyy")) -> 08/2026 | W36: =IF(P36="","",TEXT(P36,"mm/yyyy")) | X36: =IF(A36="","",IF(OR(R36="Fechado (Total)",R36="Fechado (Parcial)"),"Fechado|"&SUMPRODUCT((($R$2:R36="Fechado (Total)")+($R$2:R36="Fechado (Parcial)"))*($A$2:A36<>"")),"")) | Y36: =IF(A36="","",IF(D36="Indicação",SUMPRODUCT(($D$2:D36="Indicação")*($A$2:A36<>"")),"")) | Z36: =IF(Y36="","","Indicacao|"&Y36) | AA36: =IF(I36="","",TEXT(I36,"mm/yyyy")) -> 08/2026
A37: Jamiria Aparecida Vieira Reis | B37: (31) 8770-5202 | D37: Indicação | F37: Natalia | G37: 46235 | H37: Sim | I37: 46254 | J37: Sim | K37: Não | R37: =IF(N37="Sim","Fechado (Total)",IF(N37="Parcial","Fechado (Parcial)",IF(N37="Não","Perdido",IF(N37="Pendente","Pendente",IF(N37="Não precisa no momento","Não Precisa no Momento",IF(L37="Sim","Plano de Tratamento",IF(J37="Não","Não Compareceu",IF(J37="Sim","Compareceu",IF(H37="Não","Perdido",IF(H37="Sim","Consulta Marcada",IF(A37="","","Novo Paciente"))))))))))) -> Compareceu | T37: =IF(A37="","",SUMPRODUCT(($R$2:R37=R37)*($A$2:A37<>""))) -> 4 | U37: =IF(A37="","",R37&"|"&T37) -> Compareceu|4 | V37: =IF(G37="","",TEXT(G37,"mm/yyyy")) -> 08/2026 | W37: =IF(P37="","",TEXT(P37,"mm/yyyy")) | X37: =IF(A37="","",IF(OR(R37="Fechado (Total)",R37="Fechado (Parcial)"),"Fechado|"&SUMPRODUCT((($R$2:R37="Fechado (Total)")+($R$2:R37="Fechado (Parcial)"))*($A$2:A37<>"")),"")) | Y37: =IF(A37="","",IF(D37="Indicação",SUMPRODUCT(($D$2:D37="Indicação")*($A$2:A37<>"")),"")) -> 29 | Z37: =IF(Y37="","","Indicacao|"&Y37) -> Indicacao|29 | AA37: =IF(I37="","",TEXT(I37,"mm/yyyy")) -> 08/2026
A38: Laura Arruda dos Santos | B38: (31) 9296-3541 | D38: já é paciente | G38: 46244 | H38: Sim | I38: 46244 | J38: Sim | K38: Sim | L38: Sim | M38: 14000 | N38: Pendente | R38: =IF(N38="Sim","Fechado (Total)",IF(N38="Parcial","Fechado (Parcial)",IF(N38="Não","Perdido",IF(N38="Pendente","Pendente",IF(N38="Não precisa no momento","Não Precisa no Momento",IF(L38="Sim","Plano de Tratamento",IF(J38="Não","Não Compareceu",IF(J38="Sim","Compareceu",IF(H38="Não","Perdido",IF(H38="Sim","Consulta Marcada",IF(A38="","","Novo Paciente"))))))))))) -> Pendente | T38: =IF(A38="","",SUMPRODUCT(($R$2:R38=R38)*($A$2:A38<>""))) -> 9 | U38: =IF(A38="","",R38&"|"&T38) -> Pendente|9 | V38: =IF(G38="","",TEXT(G38,"mm/yyyy")) -> 08/2026 | W38: =IF(P38="","",TEXT(P38,"mm/yyyy")) | X38: =IF(A38="","",IF(OR(R38="Fechado (Total)",R38="Fechado (Parcial)"),"Fechado|"&SUMPRODUCT((($R$2:R38="Fechado (Total)")+($R$2:R38="Fechado (Parcial)"))*($A$2:A38<>"")),"")) | Y38: =IF(A38="","",IF(D38="Indicação",SUMPRODUCT(($D$2:D38="Indicação")*($A$2:A38<>"")),"")) | Z38: =IF(Y38="","","Indicacao|"&Y38) | AA38: =IF(I38="","",TEXT(I38,"mm/yyyy")) -> 08/2026
A39: Davi Norte Menezes | B39: (31) 99763-4054 | C39: fenorte@hotmail.com | D39: Indicação | G39: 46247 | H39: Sim | I39: 46255 | J39: Sim | K39: Sim | L39: Sim | M39: 3800 | N39: Sim | O39: 3800 | P39: 46259 | R39: =IF(N39="Sim","Fechado (Total)",IF(N39="Parcial","Fechado (Parcial)",IF(N39="Não","Perdido",IF(N39="Pendente","Pendente",IF(N39="Não precisa no momento","Não Precisa no Momento",IF(L39="Sim","Plano de Tratamento",IF(J39="Não","Não Compareceu",IF(J39="Sim","Compareceu",IF(H39="Não","Perdido",IF(H39="Sim","Consulta Marcada",IF(A39="","","Novo Paciente"))))))))))) -> Fechado (Total) | T39: =IF(A39="","",SUMPRODUCT(($R$2:R39=R39)*($A$2:A39<>""))) -> 15 | U39: =IF(A39="","",R39&"|"&T39) -> Fechado (Total)|15 | V39: =IF(G39="","",TEXT(G39,"mm/yyyy")) -> 08/2026 | W39: =IF(P39="","",TEXT(P39,"mm/yyyy")) -> 08/2026 | X39: =IF(A39="","",IF(OR(R39="Fechado (Total)",R39="Fechado (Parcial)"),"Fechado|"&SUMPRODUCT((($R$2:R39="Fechado (Total)")+($R$2:R39="Fechado (Parcial)"))*($A$2:A39<>"")),"")) -> Fechado|15 | Y39: =IF(A39="","",IF(D39="Indicação",SUMPRODUCT(($D$2:D39="Indicação")*($A$2:A39<>"")),"")) -> 30 | Z39: =IF(Y39="","","Indicacao|"&Y39) -> Indicacao|30 | AA39: =IF(I39="","",TEXT(I39,"mm/yyyy")) -> 08/2026
A40: Olivia Amorim Dornas | B40: (31) 99192-9145 | C40: lamorim2006@gmail.com | D40: já é paciente | G40: 46254 | H40: Sim | I40: 46255 | J40: Sim | K40: Sim | L40: Sim | M40: 3000 | N40: Sim | O40: 3000 | R40: =IF(N40="Sim","Fechado (Total)",IF(N40="Parcial","Fechado (Parcial)",IF(N40="Não","Perdido",IF(N40="Pendente","Pendente",IF(N40="Não precisa no momento","Não Precisa no Momento",IF(L40="Sim","Plano de Tratamento",IF(J40="Não","Não Compareceu",IF(J40="Sim","Compareceu",IF(H40="Não","Perdido",IF(H40="Sim","Consulta Marcada",IF(A40="","","Novo Paciente"))))))))))) -> Fechado (Total) | T40: =IF(A40="","",SUMPRODUCT(($R$2:R40=R40)*($A$2:A40<>""))) -> 16 | U40: =IF(A40="","",R40&"|"&T40) -> Fechado (Total)|16 | V40: =IF(G40="","",TEXT(G40,"mm/yyyy")) -> 08/2026 | W40: =IF(P40="","",TEXT(P40,"mm/yyyy")) | X40: =IF(A40="","",IF(OR(R40="Fechado (Total)",R40="Fechado (Parcial)"),"Fechado|"&SUMPRODUCT((($R$2:R40="Fechado (Total)")+($R$2:R40="Fechado (Parcial)"))*($A$2:A40<>"")),"")) -> Fechado|16 | Y40: =IF(A40="","",IF(D40="Indicação",SUMPRODUCT(($D$2:D40="Indicação")*($A$2:A40<>"")),"")) | Z40: =IF(Y40="","","Indicacao|"&Y40) | AA40: =IF(I40="","",TEXT(I40,"mm/yyyy")) -> 08/2026
...

Sheet Kanban
A1: 🆕 Novo Paciente | D1: 📅 Consulta Marcada | G1: ❌ Não Compareceu | J1: ✅ Compareceu | M1: 💰 Plano de Tratamento | P1: 🎉 Fechado | S1: ⚠️ Perdido | V1: 🕐 Pendente | Y1: 🤔 Não Precisa no Momento
A2: Nome | B2: Data Contato | D2: Nome | E2: Data Consulta | G2: Nome | H2: Data Consulta | J2: Nome | K2: Radiografia? | M2: Nome | N2: Valor Orçado | P2: Nome | Q2: Valor Fechado | S2: Nome | T2: Motivo | V2: Nome | W2: Motivo | Y2: Nome | Z2: Motivo
A3: {=IFERROR(INDEX(Pacientes!$A:$A, MATCH("Novo Paciente|1", Pacientes!$U:$U, 0)), "")} -> João Gabriel Cardoso de Oliveira | B3: {=IFERROR(INDEX(Pacientes!$G:$G, MATCH("Novo Paciente|1", Pacientes!$U:$U, 0)), "")} -> 45511 | D3: {=IFERROR(INDEX(Pacientes!$A:$A, MATCH("Consulta Marcada|1", Pacientes!$U:$U, 0)), "")} | E3: {=IFERROR(INDEX(Pacientes!$I:$I, MATCH("Consulta Marcada|1", Pacientes!$U:$U, 0)), "")} | G3: {=IFERROR(INDEX(Pacientes!$A:$A, MATCH("Não Compareceu|1", Pacientes!$U:$U, 0)), "")} -> Gabriela Mendonça Pinheiro de Melo | H3: {=IFERROR(INDEX(Pacientes!$I:$I, MATCH("Não Compareceu|1", Pacientes!$U:$U, 0)), "")} -> 46251 | J3: {=IFERROR(INDEX(Pacientes!$A:$A, MATCH("Compareceu|1", Pacientes!$U:$U, 0)), "")} -> Gabriel da Rocha Bastos | K3: {=IFERROR(INDEX(Pacientes!$K:$K, MATCH("Compareceu|1", Pacientes!$U:$U, 0)), "")} -> Sim | M3: {=IFERROR(INDEX(Pacientes!$A:$A, MATCH("Plano de Tratamento|1", Pacientes!$U:$U, 0)), "")} | N3: {=IFERROR(INDEX(Pacientes!$M:$M, MATCH("Plano de Tratamento|1", Pacientes!$U:$U, 0)), "")} | P3: {=IFERROR(INDEX(Pacientes!$A:$A, MATCH("Fechado|1", Pacientes!$X:$X, 0)), "")} -> Julia da Silva Costa | Q3: {=IFERROR(INDEX(Pacientes!$O:$O, MATCH("Fechado|1", Pacientes!$X:$X, 0)), "")} -> 14700 | S3: {=IFERROR(INDEX(Pacientes!$A:$A, MATCH("Perdido|1", Pacientes!$U:$U, 0)), "")} -> Andrea Reis Ferreira de Melo | T3: {=IFERROR(INDEX(Pacientes!$Q:$Q, MATCH("Perdido|1", Pacientes!$U:$U, 0)), "")} -> Sem orçamento no momento | V3: {=IFERROR(INDEX(Pacientes!$A:$A, MATCH("Pendente|1", Pacientes!$U:$U, 0)), "")} -> Esther Andrade dos Santos | W3: {=IFERROR(INDEX(Pacientes!$S:$S, MATCH("Pendente|1", Pacientes!$U:$U, 0)), "")} -> Quer preparar a filha para o aparelho fixo (hyrax e grade) / Chamar em Dezembro | Y3: {=IFERROR(INDEX(Pacientes!$A:$A, MATCH("Não Precisa no Momento|1", Pacientes!$U:$U, 0)), "")} | Z3: {=IFERROR(INDEX(Pacientes!$S:$S, MATCH("Não Precisa no Momento|1", Pacientes!$U:$U, 0)), "")}
A4: {=IFERROR(INDEX(Pacientes!$A:$A, MATCH("Novo Paciente|2", Pacientes!$U:$U, 0)), "")} -> Paulo Maulais | B4: {=IFERROR(INDEX(Pacientes!$G:$G, MATCH("Novo Paciente|2", Pacientes!$U:$U, 0)), "")} -> 46258 | D4: {=IFERROR(INDEX(Pacientes!$A:$A, MATCH("Consulta Marcada|2", Pacientes!$U:$U, 0)), "")} | E4: {=IFERROR(INDEX(Pacientes!$I:$I, MATCH("Consulta Marcada|2", Pacientes!$U:$U, 0)), "")} | G4: {=IFERROR(INDEX(Pacientes!$A:$A, MATCH("Não Compareceu|2", Pacientes!$U:$U, 0)), "")} | H4: {=IFERROR(INDEX(Pacientes!$I:$I, MATCH("Não Compareceu|2", Pacientes!$U:$U, 0)), "")} | J4: {=IFERROR(INDEX(Pacientes!$A:$A, MATCH("Compareceu|2", Pacientes!$U:$U, 0)), "")} -> Joaquim Manduca Campos | K4: {=IFERROR(INDEX(Pacientes!$K:$K, MATCH("Compareceu|2", Pacientes!$U:$U, 0)), "")} -> Não | M4: {=IFERROR(INDEX(Pacientes!$A:$A, MATCH("Plano de Tratamento|2", Pacientes!$U:$U, 0)), "")} | N4: {=IFERROR(INDEX(Pacientes!$M:$M, MATCH("Plano de Tratamento|2", Pacientes!$U:$U, 0)), "")} | P4: {=IFERROR(INDEX(Pacientes!$A:$A, MATCH("Fechado|2", Pacientes!$X:$X, 0)), "")} -> Fernanda Bueno Teixeira Costa | Q4: {=IFERROR(INDEX(Pacientes!$O:$O, MATCH("Fechado|2", Pacientes!$X:$X, 0)), "")} -> 11400 | S4: {=IFERROR(INDEX(Pacientes!$A:$A, MATCH("Perdido|2", Pacientes!$U:$U, 0)), "")} -> Hiltonn Muniz Cordeiro | T4: {=IFERROR(INDEX(Pacientes!$Q:$Q, MATCH("Perdido|2", Pacientes!$U:$U, 0)), "")} -> Sem orçamento no momento | V4: {=IFERROR(INDEX(Pacientes!$A:$A, MATCH("Pendente|2", Pacientes!$U:$U, 0)), "")} -> Felipe da Cunha Pereira Rocha Lacerda | W4: =IFERROR(INDEX(Pacientes!$S:$S, MATCH("Pendente|2", Pacientes!$U:$U, 0)), "") -> 0 | Y4: {=IFERROR(INDEX(Pacientes!$A:$A, MATCH("Não Precisa no Momento|2", Pacientes!$U:$U, 0)), "")} | Z4: {=IFERROR(INDEX(Pacientes!$S:$S, MATCH("Não Precisa no Momento|2", Pacientes!$U:$U, 0)), "")}
A5: {=IFERROR(INDEX(Pacientes!$A:$A, MATCH("Novo Paciente|3", Pacientes!$U:$U, 0)), "")} -> Luisa Mundim (filhas) | B5: {=IFERROR(INDEX(Pacientes!$G:$G, MATCH("Novo Paciente|3", Pacientes!$U:$U, 0)), "")} -> 46258 | D5: {=IFERROR(INDEX(Pacientes!$A:$A, MATCH("Consulta Marcada|3", Pacientes!$U:$U, 0)), "")} | E5: {=IFERROR(INDEX(Pacientes!$I:$I, MATCH("Consulta Marcada|3", Pacientes!$U:$U, 0)), "")} | G5: {=IFERROR(INDEX(Pacientes!$A:$A, MATCH("Não Compareceu|3", Pacientes!$U:$U, 0)), "")} | H5: {=IFERROR(INDEX(Pacientes!$I:$I, MATCH("Não Compareceu|3", Pacientes!$U:$U, 0)), "")} | J5: {=IFERROR(INDEX(Pacientes!$A:$A, MATCH("Compareceu|3", Pacientes!$U:$U, 0)), "")} -> Maried Guimarães Manduca Campos | K5: {=IFERROR(INDEX(Pacientes!$K:$K, MATCH("Compareceu|3", Pacientes!$U:$U, 0)), "")} -> Não | M5: {=IFERROR(INDEX(Pacientes!$A:$A, MATCH("Plano de Tratamento|3", Pacientes!$U:$U, 0)), "")} | N5: {=IFERROR(INDEX(Pacientes!$M:$M, MATCH("Plano de Tratamento|3", Pacientes!$U:$U, 0)), "")} | P5: {=IFERROR(INDEX(Pacientes!$A:$A, MATCH("Fechado|3", Pacientes!$X:$X, 0)), "")} -> Guilherme Moraes | Q5: {=IFERROR(INDEX(Pacientes!$O:$O, MATCH("Fechado|3", Pacientes!$X:$X, 0)), "")} -> 8567.86 | S5: {=IFERROR(INDEX(Pacientes!$A:$A, MATCH("Perdido|3", Pacientes!$U:$U, 0)), "")} -> Estevão Nobre Carrato | T5: {=IFERROR(INDEX(Pacientes!$Q:$Q, MATCH("Perdido|3", Pacientes!$U:$U, 0)), "")} -> Sem orçamento no momento | V5: {=IFERROR(INDEX(Pacientes!$A:$A, MATCH("Pendente|3", Pacientes!$U:$U, 0)), "")} -> Fernando Ferreira Medeiros | W5: {=IFERROR(INDEX(Pacientes!$S:$S, MATCH("Pendente|3", Pacientes!$U:$U, 0)), "")} -> ainda não nos deu retorna a respeito | Y5: {=IFERROR(INDEX(Pacientes!$A:$A, MATCH("Não Precisa no Momento|3", Pacientes!$U:$U, 0)), "")} | Z5: {=IFERROR(INDEX(Pacientes!$S:$S, MATCH("Não Precisa no Momento|3", Pacientes!$U:$U, 0)), "")}
A6: {=IFERROR(INDEX(Pacientes!$A:$A, MATCH("Novo Paciente|4", Pacientes!$U:$U, 0)), "")} -> Raquel Rabelo (filhas) | B6: =IFERROR(INDEX(Pacientes!$G:$G, MATCH("Novo Paciente|4", Pacientes!$U:$U, 0)), "") -> 0 | D6: {=IFERROR(INDEX(Pacientes!$A:$A, MATCH("Consulta Marcada|4", Pacientes!$U:$U, 0)), "")} | E6: {=IFERROR(INDEX(Pacientes!$I:$I, MATCH("Consulta Marcada|4", Pacientes!$U:$U, 0)), "")} | G6: {=IFERROR(INDEX(Pacientes!$A:$A, MATCH("Não Compareceu|4", Pacientes!$U:$U, 0)), "")} | H6: {=IFERROR(INDEX(Pacientes!$I:$I, MATCH("Não Compareceu|4", Pacientes!$U:$U, 0)), "")} | J6: =IFERROR(INDEX(Pacientes!$A:$A, MATCH("Compareceu|4", Pacientes!$U:$U, 0)), "") -> Jamiria Aparecida Vieira Reis | K6: {=IFERROR(INDEX(Pacientes!$K:$K, MATCH("Compareceu|4", Pacientes!$U:$U, 0)), "")} -> Não | M6: {=IFERROR(INDEX(Pacientes!$A:$A, MATCH("Plano de Tratamento|4", Pacientes!$U:$U, 0)), "")} | N6: {=IFERROR(INDEX(Pacientes!$M:$M, MATCH("Plano de Tratamento|4", Pacientes!$U:$U, 0)), "")} | P6: {=IFERROR(INDEX(Pacientes!$A:$A, MATCH("Fechado|4", Pacientes!$X:$X, 0)), "")} -> Bernardo Vieira Bersan El Bizri | Q6: {=IFERROR(INDEX(Pacientes!$O:$O, MATCH("Fechado|4", Pacientes!$X:$X, 0)), "")} -> 3433.17 | S6: {=IFERROR(INDEX(Pacientes!$A:$A, MATCH("Perdido|4", Pacientes!$U:$U, 0)), "")} -> Felipe Ribeiro Tostes de Menezes | T6: =IFERROR(INDEX(Pacientes!$Q:$Q, MATCH("Perdido|4", Pacientes!$U:$U, 0)), "") -> 0 | V6: {=IFERROR(INDEX(Pacientes!$A:$A, MATCH("Pendente|4", Pacientes!$U:$U, 0)), "")} -> Serena Catão de Miranda | W6: =IFERROR(INDEX(Pacientes!$S:$S, MATCH("Pendente|4", Pacientes!$U:$U, 0)), "") -> 0 | Y6: {=IFERROR(INDEX(Pacientes!$A:$A, MATCH("Não Precisa no Momento|4", Pacientes!$U:$U, 0)), "")} | Z6: {=IFERROR(INDEX(Pacientes!$S:$S, MATCH("Não Precisa no Momento|4", Pacientes!$U:$U, 0)), "")}
A7: {=IFERROR(INDEX(Pacientes!$A:$A, MATCH("Novo Paciente|5", Pacientes!$U:$U, 0)), "")} | B7: {=IFERROR(INDEX(Pacientes!$G:$G, MATCH("Novo Paciente|5", Pacientes!$U:$U, 0)), "")} | D7: {=IFERROR(INDEX(Pacientes!$A:$A, MATCH("Consulta Marcada|5", Pacientes!$U:$U, 0)), "")} | E7: {=IFERROR(INDEX(Pacientes!$I:$I, MATCH("Consulta Marcada|5", Pacientes!$U:$U, 0)), "")} | G7: {=IFERROR(INDEX(Pacientes!$A:$A, MATCH("Não Compareceu|5", Pacientes!$U:$U, 0)), "")} | H7: {=IFERROR(INDEX(Pacientes!$I:$I, MATCH("Não Compareceu|5", Pacientes!$U:$U, 0)), "")} | J7: =IFERROR(INDEX(Pacientes!$A:$A, MATCH("Compareceu|5", Pacientes!$U:$U, 0)), "") -> Stella Amorim Dornas | K7: {=IFERROR(INDEX(Pacientes!$K:$K, MATCH("Compareceu|5", Pacientes!$U:$U, 0)), "")} -> Sim | M7: {=IFERROR(INDEX(Pacientes!$A:$A, MATCH("Plano de Tratamento|5", Pacientes!$U:$U, 0)), "")} | N7: {=IFERROR(INDEX(Pacientes!$M:$M, MATCH("Plano de Tratamento|5", Pacientes!$U:$U, 0)), "")} | P7: {=IFERROR(INDEX(Pacientes!$A:$A, MATCH("Fechado|5", Pacientes!$X:$X, 0)), "")} -> Miguel Gonzalez Bidoia | Q7: {=IFERROR(INDEX(Pacientes!$O:$O, MATCH("Fechado|5", Pacientes!$X:$X, 0)), "")} -> 6650 | S7: {=IFERROR(INDEX(Pacientes!$A:$A, MATCH("Perdido|5", Pacientes!$U:$U, 0)), "")} -> Gabriela Ribeiro Tostes de Menezes | T7: =IFERROR(INDEX(Pacientes!$Q:$Q, MATCH("Perdido|5", Pacientes!$U:$U, 0)), "") -> 0 | V7: {=IFERROR(INDEX(Pacientes!$A:$A, MATCH("Pendente|5", Pacientes!$U:$U, 0)), "")} -> Kezia Cristina Teodoro dos Santos | W7: =IFERROR(INDEX(Pacientes!$S:$S, MATCH("Pendente|5", Pacientes!$U:$U, 0)), "") -> 0 | Y7: {=IFERROR(INDEX(Pacientes!$A:$A, MATCH("Não Precisa no Momento|5", Pacientes!$U:$U, 0)), "")} | Z7: {=IFERROR(INDEX(Pacientes!$S:$S, MATCH("Não Precisa no Momento|5", Pacientes!$U:$U, 0)), "")}
A8: {=IFERROR(INDEX(Pacientes!$A:$A, MATCH("Novo Paciente|6", Pacientes!$U:$U, 0)), "")} | B8: {=IFERROR(INDEX(Pacientes!$G:$G, MATCH("Novo Paciente|6", Pacientes!$U:$U, 0)), "")} | D8: {=IFERROR(INDEX(Pacientes!$A:$A, MATCH("Consulta Marcada|6", Pacientes!$U:$U, 0)), "")} | E8: {=IFERROR(INDEX(Pacientes!$I:$I, MATCH("Consulta Marcada|6", Pacientes!$U:$U, 0)), "")} | G8: {=IFERROR(INDEX(Pacientes!$A:$A, MATCH("Não Compareceu|6", Pacientes!$U:$U, 0)), "")} | H8: {=IFERROR(INDEX(Pacientes!$I:$I, MATCH("Não Compareceu|6", Pacientes!$U:$U, 0)), "")} | J8: =IFERROR(INDEX(Pacientes!$A:$A, MATCH("Compareceu|6", Pacientes!$U:$U, 0)), "") -> Felipe Terra Cunha | K8: {=IFERROR(INDEX(Pacientes!$K:$K, MATCH("Compareceu|6", Pacientes!$U:$U, 0)), "")} -> Sim | M8: {=IFERROR(INDEX(Pacientes!$A:$A, MATCH("Plano de Tratamento|6", Pacientes!$U:$U, 0)), "")} | N8: {=IFERROR(INDEX(Pacientes!$M:$M, MATCH("Plano de Tratamento|6", Pacientes!$U:$U, 0)), "")} | P8: {=IFERROR(INDEX(Pacientes!$A:$A, MATCH("Fechado|6", Pacientes!$X:$X, 0)), "")} -> Laura Gomes Souto Morato | Q8: {=IFERROR(INDEX(Pacientes!$O:$O, MATCH("Fechado|6", Pacientes!$X:$X, 0)), "")} -> 15800 | S8: {=IFERROR(INDEX(Pacientes!$A:$A, MATCH("Perdido|6", Pacientes!$U:$U, 0)), "")} -> Ana Cláudia Ribeiro Marzinetti Dias | T8: =IFERROR(INDEX(Pacientes!$Q:$Q, MATCH("Perdido|6", Pacientes!$U:$U, 0)), "") -> 0 | V8: {=IFERROR(INDEX(Pacientes!$A:$A, MATCH("Pendente|6", Pacientes!$U:$U, 0)), "")} -> Eduardo Lamaita Figueiredo | W8: =IFERROR(INDEX(Pacientes!$S:$S, MATCH("Pendente|6", Pacientes!$U:$U, 0)), "") -> 0 | Y8: {=IFERROR(INDEX(Pacientes!$A:$A, MATCH("Não Precisa no Momento|6", Pacientes!$U:$U, 0)), "")} | Z8: {=IFERROR(INDEX(Pacientes!$S:$S, MATCH("Não Precisa no Momento|6", Pacientes!$U:$U, 0)), "")}
